Workbook

Sheet Estimación
A1: Estimación de esfuerzos por módulos o componentes — VitalMind AI
J2: Escala de dificultad | K2: Simple | L2: Muy fácil | M2: Fácil | N2: Normal | O2: Difícil | P2: Muy difícil
J3: Horas | K3: 4 | L3: 8 | M3: 16 | N3: 24 | O3: 32 | P3: 40
A5: <Módulo> ANÁLISIS Y DISEÑO | B5: Simple | C5: Muy fácil | D5: Fácil | E5: Normal | F5: Difícil | G5: Muy difícil | H5: Horas
A6: Levantamiento y validación de requisitos funcionales | E6: 1 | H6: 24 | J6: Agenda y recursos
A7: Definición de arquitectura general del sistema | F7: 1 | H7: 32 | J7: Indicador | K7: 1 recurso | L7: 2 recursos | M7: 3 recursos | N7: 4 recursos | O7: 5 recursos
A8: Diseño del flujo de integración Frontend–Backend–ML | F8: 1 | H8: 32 | J8: Horas por recurso | K8: =$H$103/1 -> 2192 | L8: =$H$103/2 -> 1096 | M8: =$H$103/3 -> 730.66667 | N8: =$H$103/4 -> 548 | O8: =$H$103/5 -> 438.4
A9: Diseño del modelo entidad–relación | E9: 1 | H9: 24 | J9: Días hábiles | K9: =K8/8 -> 274 | L9: =L8/8 -> 137 | M9: =M8/8 -> 91.333333 | N9: =N8/8 -> 68.5 | O9: =O8/8 -> 54.8
A10: Definición de contratos de API y estructuras JSON | E10: 1 | H10: 24 | J10: Semanas | K10: =K9/5 -> 54.8 | L10: =L9/5 -> 27.4 | M10: =M9/5 -> 18.266667 | N10: =N9/5 -> 13.7 | O10: =O9/5 -> 10.96
A11: Diseño de prototipos y experiencia de usuario | E11: 1 | H11: 24 | J11: Meses | K11: =K10/4 -> 13.7 | L11: =L10/4 -> 6.85 | M11: =M10/4 -> 4.5666667 | N11: =N10/4 -> 3.425 | O11: =O10/4 -> 2.74
A12: Total ANÁLISIS Y DISEÑO | H12: {=SUM(H6:H11)} -> 160
A14: <Módulo> DATOS, ETL Y DATASET | B14: Simple | C14: Muy fácil | D14: Fácil | E14: Normal | F14: Difícil | G14: Muy difícil | H14: Horas | J14: Resumen por módulo
A15: Análisis de fuentes de datos y esquema MySQL | E15: 1 | H15: 24 | J15: Módulo | K15: Horas | L15: % del total | M15: Semanas (1 recurso)
A16: Definición del diccionario de datos | E16: 1 | H16: 24 | J16: ANÁLISIS Y DISEÑO | K16: =H12 -> 160 | L16: =K16/$H$103 -> 0.072992701 | M16: =K16/40 -> 4
A17: Definición de reglas de simulación | E17: 1 | H17: 24 | J17: DATOS, ETL Y DATASET | K17: =H25 -> 248 | L17: =K17/$H$103 -> 0.11313869 | M17: =K17/40 -> 6.2
A18: Desarrollo del script generador de datos sintéticos | F18: 1 | H18: 32 | J18: MACHINE LEARNING | K18: =H42 -> 400 | L18: =K18/$H$103 -> 0.18248175 | M18: =K18/40 -> 10
A19: Generación del dataset original | D19: 1 | H19: 16 | J19: MICROSERVICIO ML | K19: =H56 -> 296 | L19: =K19/$H$103 -> 0.1350365 | M19: =K19/40 -> 7.4
A20: Validación de tipos, rangos y consistencia | E20: 1 | H20: 24 | J20: BACKEND Y BASE DE DATOS | K20: =H71 -> 368 | L20: =K20/$H$103 -> 0.16788321 | M20: =K20/40 -> 9.2
A21: Limpieza y transformación del dataset | F21: 1 | H21: 32 | J21: FRONTEND | K21: =H86 -> 360 | L21: =K21/$H$103 -> 0.16423358 | M21: =K21/40 -> 9
A22: División temporal en entrenamiento, validación y prueba | E22: 1 | H22: 24 | J22: PRUEBAS, DESPLIEGUE Y CIERRE | K22: =H101 -> 360 | L22: =K22/$H$103 -> 0.16423358 | M22: =K22/40 -> 9
A23: Preparación de metadatos de imputación | E23: 1 | H23: 24
A24: Documentación del proceso ETL | E24: 1 | H24: 24
A25: Total DATOS, ETL Y DATASET | H25: =SUM(H15:H24) -> 248
A27: <Módulo> MACHINE LEARNING | B27: Simple | C27: Muy fácil | D27: Fácil | E27: Normal | F27: Difícil | G27: Muy difícil | H27: Horas
A28: Análisis exploratorio de datos (EDA) | F28: 1 | H28: 32
A29: Selección de variables para clasificación de riesgo | E29: 1 | H29: 24
A30: Entrenamiento de modelos de clasificación | F30: 1 | H30: 32
A31: Ajuste de hiperparámetros del clasificador | F31: 1 | H31: 32
A32: Evaluación final del clasificador de riesgo | E32: 1 | H32: 24
A33: Selección de variables para regresión de bienestar | E33: 1 | H33: 24
A34: Entrenamiento de modelos de regresión | F34: 1 | H34: 32
A35: Ajuste de hiperparámetros del regresor | F35: 1 | H35: 32
A36: Evaluación final del regresor de bienestar | E36: 1 | H36: 24
A37: Segmentación de perfiles con K-Means | F37: 1 | H37: 32
A38: Detección de anomalías con Isolation Forest | F38: 1 | H38: 32
A39: Serialización y versionado de modelos | E39: 1 | H39: 24
A40: Pruebas locales de inferencia | E40: 1 | H40: 24
A41: Documentación de métricas, limitaciones y resultados | F41: 1 | H41: 32
A42: Total MACHINE LEARNING | H42: =SUM(H28:H41) -> 400
A44: <Módulo> MICROSERVICIO ML | B44: Simple | C44: Muy fácil | D44: Fácil | E44: Normal | F44: Difícil | G44: Muy difícil | H44: Horas
...

Sheet Costos
B2: Estimación de costos — VitalMind AI | H2: Costo por hora (MXN) | I2: 175
B4: Costo y duración por número de recursos
B5: Tiempo / recursos | C5: 1 | D5: 2 | E5: 3 | F5: =C5/4 -> 0.25 | G5: =D5/4 -> 0.5
B6: Horas totales | C6: =Estimación!$H$103 -> 2192 | D6: =Estimación!$H$103 -> 2192 | E6: =Estimación!$H$103 -> 2192 | F6: =Estimación!$H$103 -> 2192 | G6: =Estimación!$H$103 -> 2192
B7: Horas por recurso | C7: =C6/1 -> 2192 | D7: =D6/2 -> 1096 | E7: =E6/3 -> 730.66667 | F7: =F6/4 -> 548 | G7: =G6/5 -> 438.4
B8: Semanas estimadas | C8: =C7/40 -> 54.8 | D8: =D7/40 -> 27.4 | E8: =E7/40 -> 18.266667 | F8: =F7/40 -> 13.7 | G8: =G7/40 -> 10.96
B9: Meses estimados | C9: =C8/4 -> 13.7 | D9: =D8/4 -> 6.85 | E9: =E8/4 -> 4.5666667 | F9: =F8/4 -> 3.425 | G9: =G8/4 -> 2.74
B10: Costo total | C10: =C6*$I$2 -> 383600 | D10: =D6*$I$2 -> 383600 | E10: =E6*$I$2 -> 383600 | F10: =F6*$I$2 -> 383600 | G10: =G6*$I$2 -> 383600
B12: Desglose del costo del proyecto | C12: =(C8*50)/100 -> 27.4 | D12: =(D8*50)/100 -> 13.7 | E12: =(E8*50)/100 -> 9.1333333 | F12: =(F8*50)/100 -> 6.85 | G12: =(G8*50)/100 -> 5.48
B13: Concepto / recursos | C13: =(C8*30)/100 -> 16.44 | D13: =(D8*30)/100 -> 8.22 | E13: =(E8*30)/100 -> 5.48 | F13: =(F8*30)/100 -> 4.11 | G13: =(G8*30)/100 -> 3.288
B14: Desarrollo y datos (55%) | C14: =C$10*0.55 -> 210980 | D14: =D$10*0.55 -> 210980 | E14: =E$10*0.55 -> 210980 | F14: =F$10*0.55 -> 210980 | G14: =G$10*0.55 -> 210980
B15: Infraestructura y herramientas (15%) | C15: =C$10*0.15 -> 57540 | D15: =D$10*0.15 -> 57540 | E15: =E$10*0.15 -> 57540 | F15: =F$10*0.15 -> 57540 | G15: =G$10*0.15 -> 57540
B16: Pruebas y aseguramiento de calidad (10%) | C16: =C$10*0.1 -> 38360 | D16: =D$10*0.1 -> 38360 | E16: =E$10*0.1 -> 38360 | F16: =F$10*0.1 -> 38360 | G16: =G$10*0.1 -> 38360
B17: Gestión y documentación (10%) | C17: =C$10*0.1 -> 38360 | D17: =D$10*0.1 -> 38360 | E17: =E$10*0.1 -> 38360 | F17: =F$10*0.1 -> 38360 | G17: =G$10*0.1 -> 38360
B18: Contingencia (5%) | C18: =C$10*0.05 -> 19180 | D18: =D$10*0.05 -> 19180 | E18: =E$10*0.05 -> 19180 | F18: =F$10*0.05 -> 19180 | G18: =G$10*0.05 -> 19180
B19: Ganancia / reserva (5%) | C19: =C$10*0.05 -> 19180 | D19: =D$10*0.05 -> 19180 | E19: =E$10*0.05 -> 19180 | F19: =F$10*0.05 -> 19180 | G19: =G$10*0.05 -> 19180
B20: TOTAL | C20: =SUM(C14:C19) -> 383600 | D20: =SUM(D14:D19) -> 383600 | E20: =SUM(E14:E19) -> 383600 | F20: =SUM(F14:F19) -> 383600 | G20: =SUM(G14:G19) -> 383600
B23: Costo por módulo
B24: Módulo | C24: Horas | D24: % esfuerzo | E24: Costo
B25: ANÁLISIS Y DISEÑO | C25: =Estimación!H12 -> 160 | D25: =C25/Estimación!$H$103 -> 0.072992701 | E25: =C25*$I$2 -> 28000
B26: DATOS, ETL Y DATASET | C26: =Estimación!H25 -> 248 | D26: =C26/Estimación!$H$103 -> 0.11313869 | E26: =C26*$I$2 -> 43400
B27: MACHINE LEARNING | C27: =Estimación!H42 -> 400 | D27: =C27/Estimación!$H$103 -> 0.18248175 | E27: =C27*$I$2 -> 70000
B28: MICROSERVICIO ML | C28: =Estimación!H56 -> 296 | D28: =C28/Estimación!$H$103 -> 0.1350365 | E28: =C28*$I$2 -> 51800
B29: BACKEND Y BASE DE DATOS | C29: =Estimación!H71 -> 368 | D29: =C29/Estimación!$H$103 -> 0.16788321 | E29: =C29*$I$2 -> 64400
B30: FRONTEND | C30: =Estimación!H86 -> 360 | D30: =C30/Estimación!$H$103 -> 0.16423358 | E30: =C30*$I$2 -> 63000
B31: PRUEBAS, DESPLIEGUE Y CIERRE | C31: =Estimación!H101 -> 360 | D31: =C31/Estimación!$H$103 -> 0.16423358 | E31: =C31*$I$2 -> 63000

Sheet Resumen
A1: Resumen ejecutivo de estimación — VitalMind AI
A3: Indicador | B3: Valor
A4: Horas totales | B4: =Estimación!H103 -> 2192
A5: Costo por hora | B5: =Costos!I2 -> 175
A6: Costo estimado | B6: =B4*B5 -> 383600
A7: Semanas con 1 recurso | B7: =B4/40 -> 54.8
A8: Semanas con 5 recursos | B8: =B4/(40*5) -> 10.96
A11: Módulo | B11: Horas | C11: % del total | D11: Costo estimado
A12: ANÁLISIS Y DISEÑO | B12: =Estimación!H12 -> 160 | C12: =B12/$B$4 -> 0.072992701 | D12: =B12*$B$5 -> 28000
A13: DATOS, ETL Y DATASET | B13: =Estimación!H25 -> 248 | C13: =B13/$B$4 -> 0.11313869 | D13: =B13*$B$5 -> 43400
A14: MACHINE LEARNING | B14: =Estimación!H42 -> 400 | C14: =B14/$B$4 -> 0.18248175 | D14: =B14*$B$5 -> 70000
A15: MICROSERVICIO ML | B15: =Estimación!H56 -> 296 | C15: =B15/$B$4 -> 0.1350365 | D15: =B15*$B$5 -> 51800
A16: BACKEND Y BASE DE DATOS | B16: =Estimación!H71 -> 368 | C16: =B16/$B$4 -> 0.16788321 | D16: =B16*$B$5 -> 64400
A17: FRONTEND | B17: =Estimación!H86 -> 360 | C17: =B17/$B$4 -> 0.16423358 | D17: =B17*$B$5 -> 63000
A18: PRUEBAS, DESPLIEGUE Y CIERRE | B18: =Estimación!H101 -> 360 | C18: =B18/$B$4 -> 0.16423358 | D18: =B18*$B$5 -> 63000

Sheet Responsables
A1: Responsables y entregables — VitalMind AI
A3: Área / documento | B3: Responsable principal | C3: Colaboración | D3: Entregables | E3: Estado | F3: Observaciones
A4: data-sources.md | B4: Michelle | C4: Backend | D4: CSV original, CSV procesado y script generador | E4: Completado | F4: Dataset sintético usado por ML
A5: data-dictionary.md | B5: Michelle | C5: Backend | D5: Diccionario de variables, tipos, unidades y rangos | E5: Completado | F5: Debe mantenerse alineado con MySQL
A6: simulation-rules.md | B6: Michelle | C6: Equipo ML | D6: Reglas, configuración, script y dataset simulado | E6: Completado | F6: Incluye anomalías y distribución de clases
A7: data-warehouse.md | B7: Carlos y Jennifer | C7: Backend | D7: SQL, diagrama, tablas, relaciones e índices | E7: En progreso | F7: Crear emotional_logs y log_date
A8: etl-process.md | B8: Backend + Michelle | C8: Base de datos | D8: Scripts extract, transform, load y logs | E8: En progreso | F8: Backend extrae/carga; ML transforma y valida
A9: model-evaluation.md | B9: Michelle | C9: Equipo ML | D9: Notebooks, métricas, reportes y modelos | E9: Completado | F9: Clasificación, regresión, clustering y anomalías
A10: api-contracts.md | B10: Backend + Michelle | C10: Frontend | D10: Swagger, rutas, ejemplos JSON y errores | E10: Completado | F10: POST /api/v1/analyze
A11: testing.md | B11: Citlalli | C11: Todo el equipo | D11: Plan, casos, resultados y evidencias | E11: En progreso | F11: ML aporta 9 pruebas automatizadas
A12: Microservicio ML | B12: Michelle | C12: Backend | D12: FastAPI, modelos, validación, BMI e imputación | E12: Completado | F12: Pendiente prueba con Backend real
A13: Integración final | B13: Backend | C13: Michelle + Frontend | D13: Consumo REST y persistencia de resultados | E13: Pendiente | F13: Depende de tablas emocionales y log_date
